<?xml version="1.0" ?>
<robot name="moss_minimal">
    <link name="base_link"/>
    <link name="shoulder_link"/>
    <link name="humerus_link"/>
    <link name="forearm_link"/>
    <link name="wrist_link"/>
    <link name="gripper_link"/>
    <joint name="shoulder_joint" type="revolute">
        <parent link="base_link"/>
        <child link="shoulder_link"/>
        <origin xyz="0 0 0.02" rpy="0 0 0"/>
        <axis xyz="0 0 -1"/>
        <limit lower="-3.1416" upper="3.1416" effort="1" velocity="1"/>
    </joint>
    <joint name="humerus_joint" type="revolute">
        <parent link="shoulder_link"/>
        <child link="humerus_link"/>
        <origin xyz="0.001 0.001 0.063" rpy="0 0 0"/>
        <axis xyz="0 -1 0"/>
        <limit lower="-3.1416" upper="3.1416" effort="1" velocity="1"/>
    </joint>
    <joint name="forearm_joint" type="revolute">
        <parent link="humerus_link"/>
        <child link="forearm_link"/>
        <origin xyz="0.121 -0.001 0.001" rpy="0 0 0"/>
        <axis xyz="0 1 0"/>
        <limit lower="-3.1416" upper="3.1416" effort="1" velocity="1"/>
    </joint>
    <joint name="wrist_joint" type="revolute">
        <parent link="forearm_link"/>
        <child link="wrist_link"/>
        <origin xyz="0.123 0.002 0.0" rpy="0 0 0"/>
        <axis xyz="0 1 0"/>
        <limit lower="-3.1416" upper="3.1416" effort="1" velocity="1"/>
    </joint>
    <joint name="gripper_joint" type="revolute">
        <parent link="wrist_link"/>
        <child link="gripper_link"/>
        <origin xyz="0.001 0.011 0.047" rpy="-1.5708 0 0"/>
        <axis xyz="1 0 0"/>
        <limit lower="-3.1416" upper="3.1416" effort="1" velocity="1"/>
    </joint>
</robot>
